# Panic & Recover

## Panic

#### TS

```ts
function example() {
  try {
    console.log("TypeScript - About to throw an error.");
    throw new Error("TypeScript - Something went wrong!");
  } catch (error) {
    console.error("TypeScript - Caught an error:", error.message);
  }
}

example();
```

#### Go

```go
package main

import "fmt"

func main() {
    defer fmt.Println("Go - Deferred call executed before panic unwinds the stack.") // defer still done before crash
    fmt.Println("Go - About to panic.")
    panic("Go - Something went wrong!") // let's crash program
    fmt.Println("Go - This will not be printed.")
}
```

## Recover

#### TS

```ts
function example() {
  try {
    console.log("TypeScript - About to throw an error.");
    throw new Error("TypeScript - Something went wrong!");
  } catch (error) {
    console.error("TypeScript - Caught and handled error:", error.message);
    // Continue execution
  }
  console.log("TypeScript - Program continues after handling the error.");
}

example();
```

#### Go

```go
package main

import "fmt"

func main() {
    defer func() {
        if r := recover(); r != nil {
            fmt.Println("Go - Recovered from panic:", r)
        }
    }() // no crash cuz use recover

    fmt.Println("Go - About to panic.")
    panic("Go - Something went wrong!")
    fmt.Println("Go - This will not be printed.")
}
```
